Workbook

Sheet Лист ответов
B2: № | C2: ЗАДАНИЕ | D2: ОТВЕТ | F2: СТАТУС
A3: 1 | B3: 1 | C3: Вычислите общую сумму начислений для всех абонентов в тенге | D3: =SUM('База данных'!D2:D624) -> 3899.58 | F3: =IF(ISERROR(IF(ROUND(D3,2)=ROUND(O3,2),"Правильный ответ","Неправильный ответ")),"Неправильный ответ",IF(ROUND(D3,2)=ROUND(O3,2),"Правильный ответ","Неправильный ответ")) -> Правильный ответ | O3: 3899.58
A4: 2 | B4: =IF(C4="","",A4) -> 2 | C4: =IF(F3="Правильный ответ","Вычислите общую продолжительность разговоров для всех абонентов в секундах","") -> Вычислите общую продолжительность разговоров для всех абонентов в секундах | D4: =SUM('База данных'!E2:E624) -> 7883 | F4: =IF(ISERROR(IF(D4=D4,"Правильный ответ","Неправильный ответ")),"Неправильный ответ",IF(D4=O4,"Правильный ответ","Неправильный ответ")) -> Правильный ответ | O4: 7883
A5: 3 | B5: =IF(C5="","",A5) -> 3 | C5: =IF(F4="Правильный ответ","Вычислите общее количество звонков всех абонентов (одна строка = один звонок)","") -> Вычислите общее количество звонков всех абонентов (одна строка = один звонок) | D5: =COUNTA('База данных'!A2:A624) -> 623 | F5: =IF(ISERROR(IF(D5=D5,"Правильный ответ","Неправильный ответ")),"Неправильный ответ",IF(D5=O5,"Правильный ответ","Неправильный ответ")) -> Правильный ответ | O5: 623
A6: 4 | B6: =IF(C6="","",A6) -> 4 | C6: =IF(F5="Правильный ответ","Вычислите общую продолжительность разговоров для всех абонентов в минутах, округлив значение до десятичного знака (математическое округление)","") -> Вычислите общую продолжительность разговоров для всех абонентов в минутах, округлив значение до десятичного знака (математическое округление) | D6: =ROUND(SUM('База данных'!E2:E624)/60,1) -> 131.4 | F6: =IF(ISERROR(IF(D6=D6,"Правильный ответ","Неправильный ответ")),"Неправильный ответ",IF(D6=O6,"Правильный ответ","Неправильный ответ")) -> Правильный ответ | O6: 131.4
A7: 5 | B7: =IF(C7="","",A7) -> 5 | C7: =IF(F6="Правильный ответ","Вычислите сумму начислений для звонков внутри сети","") -> Вычислите сумму начислений для звонков внутри сети | D7: =SUMIF('База данных'!C2:C624,"Внутри сети",'База данных'!D2:D624) -> 3172.39 | F7: =IF(ISERROR(IF(ROUND(D7,2)=ROUND(O7,2),"Правильный ответ","Неправильный ответ")),"Неправильный ответ",IF(ROUND(D7,2)=ROUND(O7,2),"Правильный ответ","Неправильный ответ")) -> Правильный ответ | O7: 3172.39
A8: 6 | B8: =IF(C8="","",A8) -> 6 | C8: =IF(F7="Правильный ответ","Вычислите продолжительность разговоров на других операторов в секундах","") -> Вычислите продолжительность разговоров на других операторов в секундах | D8: =SUMIF('База данных'!C2:C624,"На других операторов",'База данных'!E2:E624) -> 362 | F8: =IF(ISERROR(IF(D8=D8,"Правильный ответ","Неправильный ответ")),"Неправильный ответ",IF(D8=O8,"Правильный ответ","Неправильный ответ")) -> Правильный ответ | O8: 362
A9: 7 | B9: =IF(C9="","",A9) -> 7 | C9: =IF(F8="Правильный ответ","Вычислите общее количество звонков на тарифном плане 2 (одна строка = один звонок)","") -> Вычислите общее количество звонков на тарифном плане 2 (одна строка = один звонок) | D9: =COUNTIF('База данных'!B2:B624,2) -> 66 | F9: =IF(ISERROR(IF(D9=D9,"Правильный ответ","Неправильный ответ")),"Неправильный ответ",IF(D9=O9,"Правильный ответ","Неправильный ответ")) -> Правильный ответ | O9: 66
A10: 8 | B10: =IF(C10="","",A10) -> 8 | C10: =IF(F9="Правильный ответ","Вычислите среднюю стоимость одной минуты разговора всех абонентов по всем направлениям и округлите ее до сотых (математическое округление)","") -> Вычислите среднюю стоимость одной минуты разговора всех абонентов по всем направлениям и округлите ее до сотых (математическое округление) | D10: =ROUND(SUM('База данных'!D2:D624)/(SUM('База данных'!E2:E624)/60),2) -> 29.68 | F10: =IF(ISERROR(IF(D10=D10,"Правильный ответ","Неправильный ответ")),"Неправильный ответ",IF(D10=O10,"Правильный ответ","Неправильный ответ")) -> Правильный ответ | O10: 29.68
A11: 9 | B11: =IF(C11="","",A11) -> 9 | C11: =IF(F10="Правильный ответ","Вычислите среднюю продолжительность одного звонка всех абонентов по всем направлениям в секундах и округлите ее до целого числа (математическое округление)","") -> Вычислите среднюю продолжительность одного звонка всех абонентов по всем направлениям в секундах и округлите ее до целого числа (математическое округление) | D11: =ROUND(SUM('База данных'!E2:E624)/COUNT('База данных'!E2:E624),0) -> 13 | F11: =IF(ISERROR(IF(D11=D11,"Правильный ответ","Неправильный ответ")),"Неправильный ответ",IF(D11=O11,"Правильный ответ","Неправильный ответ")) -> Правильный ответ | O11: 13
A12: 10 | B12: =IF(C12="","",A12) -> 10 | C12: =IF(F11="Правильный ответ","Вычислите сумму продолжительности разговоров в секундах на городской для тарифного плана 5","") -> Вычислите сумму продолжительности разговоров в секундах на городской для тарифного плана 5 | D12: =SUMIFS('База данных'!E2:E624,'База данных'!C2:C624,"На городской",'База данных'!B2:B624,5) -> 33 | F12: =IF(ISERROR(IF(D12=D12,"Правильный ответ","Неправильный ответ")),"Неправильный ответ",IF(D12=O12,"Правильный ответ","Неправильный ответ")) -> Правильный ответ | O12: 33
A13: 11 | B13: =IF(C13="","",A13) -> 11 | C13: =IF(F12="Правильный ответ","Вычислите количество звонков на межнар для тарифного плана 1","") -> Вычислите количество звонков на межнар для тарифного плана 1 | D13: =COUNTIFS('База данных'!C2:C624,"На межнар",'База данных'!B2:B624,1) -> 6 | F13: =IF(ISERROR(IF(D13=D13,"Правильный ответ","Неправильный ответ")),"Неправильный ответ",IF(D13=O13,"Правильный ответ","Неправильный ответ")) -> Правильный ответ | O13: 6
A14: 12 | B14: =IF(C14="","",A14) -> 12 | C14: =IF(F13="Правильный ответ","Вычислите долю продолжительности внутрисетевых звонков от всех звонков. Округлите до сотых в процентах","") -> Вычислите долю продолжительности внутрисетевых звонков от всех звонков. Округлите до сотых в процентах | D14: =ROUND(SUMIF('База данных'!C2:C624,"Внутри сети",'База данных'!E2:E624)/SUM('База данных'!E2:E624),4) -> 0.9155 | F14: =IF(ISERROR(IF(D14=D14,"Правильный ответ","Неправильный ответ")),"Неправильный ответ",IF(D14=O14,"Правильный ответ","Неправильный ответ")) -> Правильный ответ | O14: 0.9155
A15: 13 | B15: =IF(C15="","",A15) -> 13 | C15: =IF(F14="Правильный ответ","Вычислите долю начислений тарифного плана 1 от общих начислений по всем тарифам. Округлите до сотых в процентах","") -> Вычислите долю начислений тарифного плана 1 от общих начислений по всем тарифам. Округлите до сотых в процентах | D15: =ROUND(SUMIF('База данных'!B2:B624,1,'База данных'!D2:D624)/SUM('База данных'!D2:D624),4) -> 0.3642 | F15: =IF(ISERROR(IF(D15=D15,"Правильный ответ","Неправильный ответ")),"Неправильный ответ",IF(D15=O15,"Правильный ответ","Неправильный ответ")) -> Правильный ответ | O15: 0.3642
A16: 14 | B16: =IF(C16="","",A16) -> 14 | C16: =IF(F15="Правильный ответ","Вычислите общее количество уникальных абонентов","") -> Вычислите общее количество уникальных абонентов | D16: {=SUM(IF(FREQUENCY('База данных'!A2:A624,'База данных'!A2:A624)>0,1))} -> 292 | F16: =IF(ISERROR(IF(D16=D16,"Правильный ответ","Неправильный ответ")),"Неправильный ответ",IF(D16=O16,"Правильный ответ","Неправильный ответ")) -> Правильный ответ | O16: 292
A17: 15 | B17: =IF(C17="","",A17) -> 15 | C17: =IF(F16="Правильный ответ","Укажите общее количество уникальных пользователей внутрисетевых звонков","") -> Укажите общее количество уникальных пользователей внутрисетевых звонков | D17: {=SUM(IF(FREQUENCY(IF('База данных'!C2:C624="Внутри сети",'База данных'!A2:A624),IF('База данных'!C2:C624="Внутри сети",'База данных'!A2:A624))>0,1))} -> 290 | F17: =IF(ISERROR(IF(D17=D17,"Правильный ответ","Неправильный ответ")),"Неправильный ответ",IF(D17=O17,"Правильный ответ","Неправильный ответ")) -> Правильный ответ | O17: 290
A18: 16 | B18: =IF(C18="","",A18) -> 16 | C18: =IF(F17="Правильный ответ","Укажите общее количество уникальных абонентов на тарифном плане 6","") -> Укажите общее количество уникальных абонентов на тарифном плане 6 | D18: {=SUM(IF(FREQUENCY(IF('База данных'!B2:B624=6,'База данных'!A2:A624),IF('База данных'!B2:B624=6,'База данных'!A2:A624))>0,1))} -> 63 | F18: =IF(ISERROR(IF(D18=D18,"Правильный ответ","Неправильный ответ")),"Неправильный ответ",IF(D18=O18,"Правильный ответ","Неправильный ответ")) -> Правильный ответ | O18: 63
A19: 17 | B19: =IF(C19="","",A19) -> 17 | C19: =IF(F18="Правильный ответ","Вычислите долю уникальных абонентов тарифного плана 2 от общего количества уникальных абонентов по всем тарифам. Округлите до сотых","") -> Вычислите долю уникальных абонентов тарифного плана 2 от общего количества уникальных абонентов по всем тарифам. Округлите до сотых | D19: {=ROUND(SUM(IF(FREQUENCY(IF('База данных'!B2:B624=2,'База данных'!A2:A624),IF('База данных'!B2:B624=2,'База данных'!A2:A624))>0,1))/292,4)} -> 0.1096 | F19: =IF(ISERROR(IF(D19=D19,"Правильный ответ","Неправильный ответ")),"Неправильный ответ",IF(D19=O19,"Правильный ответ","Неправильный ответ")) -> Правильный ответ | O19: 0.1096
A20: 18 | B20: =IF(C20="","",A20) -> 18 | C20: =IF(F19="Правильный ответ","Рассчитайте средние начисления в тенге на одного уникального абонента, округлите значение до сотых","") -> Рассчитайте средние начисления в тенге на одного уникального абонента, округлите значение до сотых | D20: {=ROUND(SUM('База данных'!D2:D624)/SUM(IF(FREQUENCY('База данных'!A2:A624,'База данных'!A2:A624)>0,1)),2)} -> 13.35 | F20: =IF(ISERROR(IF(D20=D20,"Правильный ответ","Неправильный ответ")),"Неправильный ответ",IF(D20=O20,"Правильный ответ","Неправильный ответ")) -> Правильный ответ | O20: 13.35
A21: 19 | B21: =IF(C21="","",A21) -> 19 | C21: =IF(F20="Правильный ответ","Рассчитайте среднюю продолжительность разговоров одного уникального абонента в минутах, округлите значение до десятых","") -> Рассчитайте среднюю продолжительность разговоров одного уникального абонента в минутах, округлите значение до десятых | D21: {=ROUND(SUM('База данных'!E2:E624)/SUM(IF(FREQUENCY('База данных'!A2:A624,'База данных'!A2:A624)>0,1))/60,1)} -> 0.4 | F21: =IF(ISERROR(IF(D21=D21,"Правильный ответ","Неправильный ответ")),"Неправильный ответ",IF(D21=O21,"Правильный ответ","Неправильный ответ")) -> Правильный ответ | O21: 0.4
A22: 20 | B22: =IF(C22="","",A22) -> 20 | C22: =IF(F21="Правильный ответ","Укажите продолжительность разговоров на тарифном плане, на котором сидит абонент 77010000055","") -> Укажите продолжительность разговоров на тарифном плане, на котором сидит абонент 77010000055 | D22: 2705 | F22: =IF(ISERROR(IF(D22=D22,"Правильный ответ","Неправильный ответ")),"Неправильный ответ",IF(D22=O22,"Правильный ответ","Неправильный ответ")) -> Правильный ответ | O22: 2705
A23: 21 | B23: =IF(C23="","",A23) -> 21 | C23: =IF(F22="Правильный ответ","Укажите абонента, у которого наибольшее начисление","") -> Укажите абонента, у которого наибольшее начисление | D23: {=INDEX('База данных'!A2:A624,MATCH(MAX('База данных'!D2:D624),'База данных'!D2:D624,0))} -> 77010000109 | F23: =IF(ISERROR(IF(D23=D23,"Правильный ответ","Неправильный ответ")),"Неправильный ответ",IF(D23=O23,"Правильный ответ","Неправильный ответ")) -> Правильный ответ | O23: 77010000109
A24: 22 | B24: =IF(C24="","",A24) -> 22 | C24: =IF(F23="Правильный ответ","Укажите абонента, у которого наибольшая продолжительность разговоров на тарифном плане 5","") -> Укажите абонента, у которого наибольшая продолжительность разговоров на тарифном плане 5 | D24: {=INDEX('База данных'!A2:A624,MATCH(MAX(IF('База данных'!B2:B624=5,SUMIF('База данных'!A2:A624,'База данных'!A2:A624,'База данных'!E2:E624))),SUMIF('База данных'!A2:A624,'База данных'!A2:A624,'База данных'!E2:E624),0))} -> 77010000211 | F24: =IF(ISERROR(IF(D24=D24,"Правильный ответ","Неправильный ответ")),"Неправильный ответ",IF(D24=O24,"Правильный ответ","Неправильный ответ")) -> Правильный ответ | O24: 77010000211
A25: 23 | B25: =IF(C25="","",A25) -> 23 | C25: =IF(F24="Правильный ответ","Укажите абонента, который на 7 месте по общей сумме начислений","") -> Укажите абонента, который на 7 месте по общей сумме начислений | D25: {=INDEX('База данных'!A2:A624,MATCH(LARGE(IF(MATCH('База данных'!A2:A624,'База данных'!A2:A624,0)=ROW('База данных'!A2:A624)-ROW('База данных'!A2)+1,SUMIF('База данных'!A2:A624,'База данных'!A2:A624,'База данных'!D2:D624)),7),SUMIF('База данных'!A2:A624,'База данных'!A2:A624,'База данных'!D2:D624),0))} -> 77010000133 | F25: =IF(ISERROR(IF(D25=D25,"Правильный ответ","Неправильный ответ")),"Неправильный ответ",IF(D25=O25,"Правильный ответ","Неправильный ответ")) -> Правильный ответ | O25: 77010000133
A26: 24 | B26: =IF(C26="","",A26) -> 24 | C26: =IF(F25="Правильный ответ","Какое направление не используется абонентами тарифного плана 6 (ответов может быть несколько, вписывать через запятую)","") -> Какое направление не используется абонентами тарифного плана 6 (ответов может быть несколько, вписывать через запятую) | D26: =CONCATENATE(INDEX('База данных'!C2:C624,MATCH("На городской",'База данных'!C2:C624,0)),", ",INDEX('База данных'!C2:C624,MATCH("Другое",'База данных'!C2:C624,0))) -> На городской, Другое | F26: =IF(ISERROR(IF(OR(UPPER(TRIM(LEFT(D26,SEARCH(",",D26,1)-1)))&","&UPPER(TRIM(RIGHT(D26,LEN(D26)-SEARCH(",",D26,1))))=O26&","&P26,UPPER(TRIM(LEFT(D26,SEARCH(",",D26,1)-1)))&","&UPPER(TRIM(RIGHT(D26,LEN(D26)-SEARCH(",",D26,1))))=P26&","&O26),"Правильный ответ","Неправильный ответ")),"Неправильный ответ",IF(OR(UPPER(TRIM(LEFT(D26,SEARCH(",",D26,1)-1)))&","&UPPER(TRIM(RIGHT(D26,LEN(D26)-SEARCH(",",D26,1))))=O26&","&P26,UPPER(TRIM(LEFT(D26,SEARCH(",",D26,1)-1)))&","&UPPER(TRIM(RIGHT(D26,LEN(D26)-SEARCH(",",D26,1))))=P26&","&O26),"Правильный ответ","Неправильный ответ")) -> Правильный ответ | O26: НА ГОРОДСКОЙ | P26: ДРУГОЕ
C27: =IF(F26="Правильный ответ","Тест пройден. Поздравляем!","") -> Тест пройден. Поздравляем! | D27: =SUMIF('База данных'!B:B, VLOOKUP(77010000055, 'База данных'!A:B, 2, 0), 'База данных'!E:E) -> 2705

Sheet База данных
A1: Абонент | B1: Тарифный план | C1: Направление звонка | D1: Начисления, тенге | E1: Продолжительность разговора, секунды
A2: 77010000068 | B2: 1 | C2: Внутри сети | D2: 0 | E2: 0 | H2: =TRIM(Таблиця1[[#This Row],[Абонент]]) -> 77010000068 | J2: =IF(C2="Внутри сети",A2,"") -> 77010000068 | L2: =SUMIF(B2:B624,VLOOKUP(77010000055,A2:B624,2,FALSE),E2:E624) -> 2705
A3: 77010000001 | B3: 1 | C3: Внутри сети | D3: 0.43 | E3: 1 | H3: =TRIM(Таблиця1[[#This Row],[Абонент]]) -> 77010000001 | J3: =IF(C3="Внутри сети",A3,"") -> 77010000001 | L3: {=INDEX('База данных'!A2:A624,MATCH(MAX('База данных'!D2:D624),'База данных'!D2:D624,0))} -> 77010000109
A4: 77010000003 | B4: 1 | C4: Внутри сети | D4: 0.43 | E4: 1 | H4: =TRIM(Таблиця1[[#This Row],[Абонент]]) -> 77010000003 | J4: =IF(C4="Внутри сети",A4,"") -> 77010000003
A5: 77010000004 | B5: 1 | C5: Внутри сети | D5: 0.43 | E5: 1 | H5: =TRIM(Таблиця1[[#This Row],[Абонент]]) -> 77010000004 | J5: =IF(C5="Внутри сети",A5,"") -> 77010000004 | L5: =CONCATENATE('База данных'!C2,"; ",INDEX('База данных'!C2:C624,MATCH("На городской",'База данных'!C2:C624,0))) -> Внутри сети; На городской
A6: 77010000008 | B6: 1 | C6: Внутри сети | D6: 0.43 | E6: 1 | H6: =TRIM(Таблиця1[[#This Row],[Абонент]]) -> 77010000008 | J6: =IF(C6="Внутри сети",A6,"") -> 77010000008
A7: 77010000052 | B7: 1 | C7: Внутри сети | D7: 0.43 | E7: 1 | H7: =TRIM(Таблиця1[[#This Row],[Абонент]]) -> 77010000052 | J7: =IF(C7="Внутри сети",A7,"") -> 77010000052 | L7: =CONCATENATE(INDEX('База данных'!C2:C624,MATCH("Внутри сети",'База данных'!C2:C624,0)),"; ",INDEX('База данных'!C2:C624,MATCH("На городской",'База данных'!C2:C624,0))) -> Внутри сети; На городской
A8: 77010000060 | B8: 1 | C8: Внутри сети | D8: 0.43 | E8: 1 | H8: =TRIM(Таблиця1[[#This Row],[Абонент]]) -> 77010000060 | J8: =IF(C8="Внутри сети",A8,"") -> 77010000060
A9: 77010000046 | B9: 1 | C9: Внутри сети | D9: 0.43 | E9: 1 | H9: =TRIM(Таблиця1[[#This Row],[Абонент]]) -> 77010000046 | J9: =IF(C9="Внутри сети",A9,"") -> 77010000046
A10: 77010000054 | B10: 1 | C10: Внутри сети | D10: 0.43 | E10: 1 | H10: =TRIM(Таблиця1[[#This Row],[Абонент]]) -> 77010000054 | J10: =IF(C10="Внутри сети",A10,"") -> 77010000054
A11: 77010000062 | B11: 1 | C11: Внутри сети | D11: 0.43 | E11: 1 | H11: =TRIM(Таблиця1[[#This Row],[Абонент]]) -> 77010000062 | J11: =IF(C11="Внутри сети",A11,"") -> 77010000062
A12: 77010000065 | B12: 1 | C12: Внутри сети | D12: 0.43 | E12: 1 | H12: =TRIM(Таблиця1[[#This Row],[Абонент]]) -> 77010000065 | J12: =IF(C12="Внутри сети",A12,"") -> 77010000065
A13: 77010000066 | B13: 1 | C13: Внутри сети | D13: 0.43 | E13: 1 | H13: =TRIM(Таблиця1[[#This Row],[Абонент]]) -> 77010000066 | J13: =IF(C13="Внутри сети",A13,"") -> 77010000066
A14: 77010000063 | B14: 1 | C14: На других операторов | D14: 7.43 | E14: 1 | H14: =TRIM(Таблиця1[[#This Row],[Абонент]]) -> 77010000063 | J14: =IF(C14="Внутри сети",A14,"")
A15: 77010000066 | B15: 1 | C15: Внутри сети | D15: 0.43 | E15: 1 | H15: =TRIM(Таблиця1[[#This Row],[Абонент]]) -> 77010000066 | J15: =IF(C15="Внутри сети",A15,"") -> 77010000066
A16: 77010000045 | B16: 1 | C16: Внутри сети | D16: 0.43 | E16: 1 | H16: =TRIM(Таблиця1[[#This Row],[Абонент]]) -> 77010000045 | J16: =IF(C16="Внутри сети",A16,"") -> 77010000045
A17: 77010000082 | B17: 1 | C17: Внутри сети | D17: 0.43 | E17: 1 | H17: =TRIM(Таблиця1[[#This Row],[Абонент]]) -> 77010000082 | J17: =IF(C17="Внутри сети",A17,"") -> 77010000082
A18: 77010000094 | B18: 1 | C18: Внутри сети | D18: 0.43 | E18: 1 | H18: =TRIM(Таблиця1[[#This Row],[Абонент]]) -> 77010000094 | J18: =IF(C18="Внутри сети",A18,"") -> 77010000094
A19: 77010000003 | B19: 1 | C19: Внутри сети | D19: 0.43 | E19: 1 | H19: =TRIM(Таблиця1[[#This Row],[Абонент]]) -> 77010000003 | J19: =IF(C19="Внутри сети",A19,"") -> 77010000003
... A196: 77010000051 | B196: 1 | C196: Внутри сети | D196: 6.82 | E196: 16 | H196: =TRIM(Таблиця1[[#This Row],[Абонент]]) -> 77010000051 | J196: =IF(C196="Внутри сети",A196,"") -> 77010000051
A197: 77010000071 | B197: 1 | C197: Внутри сети | D197: 6.82 | E197: 16 | H197: =TRIM(Таблиця1[[#This Row],[Абонент]]) -> 77010000071 | J197: =IF(C197="Внутри сети",A197,"") -> 77010000071 | K197: {=IF(COUNTIFS('База данных'!B2:B624,6,'База данных'!C2:C624,"Внутри сети")=0,"Внутри сети","")&IF(COUNTIFS('База данных'!B2:B624,6,'База данных'!C2:C624,"На других операторов")=0,IF(COUNTIFS('База данных'!B2:B624,6,'База данных'!C2:C624,"Внутри сети")=0,", ","")&"На других операторов","")&IF(COUNTIFS('База данных'!B2:B624,6,'База данных'!C2:C624,"На межнар")=0,IF(OR(COUNTIFS('База данных'!B2:B624,6,'База данных'!C2:C624,"Внутри сети")=0,COUNTIFS('База данных'!B2:B624,6,'База данных'!C2:C624,"На других операторов")=0),", ","")&"На межнар","")&IF(COUNTIFS('База данных'!B2:B624,6,'База данных'!C2:C624,"На городской")=0,IF(OR(COUNTIFS('База данных'!B2:B624,6,'База данных'!C2:C624,"Внутри сети")=0,COUNTIFS('База данных'!B2:B624,6,'База данных'!C2:C624,"На других операторов")=0,COUNTIFS('База данных'!B2:B624,6,'База данных'!C2:C624,"На межнар")=0),", ","")&"На городской","")} -> На городской
A198: 77010000072 | B198: 1 | C198: Внутри сети | D198: 6.82 | E198: 16 | H198: =TRIM(Таблиця1[[#This Row],[Абонент]]) -> 77010000072 | J198: =IF(C198="Внутри сети",A198,"") -> 77010000072
A199: 77010000028 | B199: 1 | C199: Внутри сети | D199: 6.82 | E199: 16 | H199: =TRIM(Таблиця1[[#This Row],[Абонент]]) -> 77010000028 | J199: =IF(C199="Внутри сети",A199,"") -> 77010000028
A200: 77010000030 | B200: 1 | C200: На других операторов | D200: 14.87 | E200: 16 | H200: =TRIM(Таблиця1[[#This Row],[Абонент]]) -> 77010000030 | J200: =IF(C200="Внутри сети",A200,"")
A201: 77010000032 | B201: 1 | C201: Внутри сети | D201: 6.82 | E201: 16 | H201: =TRIM(Таблиця1[[#This Row],[Абонент]]) -> 77010000032 | J201: =IF(C201="Внутри сети",A201,"") -> 77010000032
A202: 77010000004 | B202: 1 | C202: Внутри сети | D202: 6.82 | E202: 16 | H202: =TRIM(Таблиця1[[#This Row],[Абонент]]) -> 77010000004 | J202: =IF(C202="Внутри сети",A202,"") -> 77010000004
A203: 77010000027 | B203: 1 | C203: Внутри сети | D203: 6.82 | E203: 16 | H203: =TRIM(Таблиця1[[#This Row],[Абонент]]) -> 77010000027 | J203: =IF(C203="Внутри сети",A203,"") -> 77010000027
A204: 77010000084 | B204: 1 | C204: Внутри сети | D204: 6.82 | E204: 16 | H204: =TRIM(Таблиця1[[#This Row],[Абонент]]) -> 77010000084 | J204: =IF(C204="Внутри сети",A204,"") -> 77010000084
A205: 77010000053 | B205: 1 | C205: Внутри сети | D205: 7.25 | E205: 17 | H205: =TRIM(Таблиця1[[#This Row],[Абонент]]) -> 77010000053 | J205: =IF(C205="Внутри сети",A205,"") -> 77010000053
A206: 77010000001 | B206: 1 | C206: На других операторов | D206: 14.87 | E206: 17 | H206: =TRIM(Таблиця1[[#This Row],[Абонент]]) -> 77010000001 | J206: =IF(C206="Внутри сети",A206,"")
A207: 77010000008 | B207: 1 | C207: На городской | D207: 14.87 | E207: 17 | H207: =TRIM(Таблиця1[[#This Row],[Абонент]]) -> 77010000008 | J207: =IF(C207="Внутри сети",A207,"")
A208: 77010000019 | B208: 1 | C208: Внутри сети | D208: 7.25 | E208: 17 | H208: =TRIM(Таблиця1[[#This Row],[Абонент]]) -> 77010000019 | J208: =IF(C208="Внутри сети",A208,"") -> 77010000019
A209: 77010000038 | B209: 1 | C209: Внутри сети | D209: 7.25 | E209: 17 | H209: =TRIM(Таблиця1[[#This Row],[Абонент]]) -> 77010000038 | J209: =IF(C209="Внутри сети",A209,"") -> 77010000038
... A268: 77010000100 | B268: 2 | C268: Внутри сети | D268: 2.98 | E268: 7 | H268: =TRIM(Таблиця1[[#This Row],[Абонент]]) -> 77010000100 | J268: =IF(C268="Внутри сети",A268,"") -> 77010000100
A269: 77010000102 | B269: 2 | C269: Внутри сети | D269: 2.98 | E269: 7 | H269: =TRIM(Таблиця1[[#This Row],[Абонент]]) -> 77010000102 | J269: =IF(C269="Внутри сети",A269,"") -> 77010000102 | L269: {=IF(SUMPRODUCT(('База данных'!B2:B624=6)*('База данных'!C2:C624="Внутри сети"))=0,"Внутри сети","")&IF(SUMPRODUCT(('База данных'!B2:B624=6)*('База данных'!C2:C624="На других операторов"))=0,IF(SUMPRODUCT(('База данных'!B2:B624=6)*('База данных'!C2:C624="Внутри сети"))=0,", ","")&"На других операторов","")&IF(SUMPRODUCT(('База данных'!B2:B624=6)*('База данных'!C2:C624="На межнар"))=0,IF(OR(SUMPRODUCT(('База данных'!B2:B624=6)*('База данных'!C2:C624="Внутри сети"))=0,SUMPRODUCT(('База данных'!B2:B624=6)*('База данных'!C2:C624="На других операторов"))=0),", ","")&"На межнар","")&IF(SUMPRODUCT(('База данных'!B2:B624=6)*('База данных'!C2:C624="На городской"))=0,IF(OR(SUMPRODUCT(('База данных'!B2:B624=6)*('База данных'!C2:C624="Внутри сети"))=0,SUMPRODUCT(('База данных'!B2:B624=6)*('База данных'!C2:C624="На других операторов"))=0,SUMPRODUCT(('База данных'!B2:B624=6)*('База данных'!C2:C624="На межнар"))=0),", ","")&"На городской","")} -> На городской
A270: 77010000124 | B270: 2 | C270: Внутри сети | D270: 3.41 | E270: 8 | H270: =TRIM(Таблиця1[[#This Row],[Абонент]]) -> 77010000124 | J270: =IF(C270="Внутри сети",A270,"") -> 77010000124
A271: 77010000111 | B271: 2 | C271: Внутри сети | D271: 3.84 | E271: 9 | H271: =TRIM(Таблиця1[[#This Row],[Абонент]]) -> 77010000111 | J271: =IF(C271="Внутри сети",A271,"") -> 77010000111
A272: 77010000129 | B272: 2 | C272: Внутри сети | D272: 3.84 | E272: 9 | H272: =TRIM(Таблиця1[[#This Row],[Абонент]]) -> 77010000129 | J272: =IF(C272="Внутри сети",A272,"") -> 77010000129
A273: 77010000110 | B273: 2 | C273: Внутри сети | D273: 3.84 | E273: 9 | H273: =TRIM(Таблиця1[[#This Row],[Абонент]]) -> 77010000110 | J273: =IF(C273="Внутри сети",A273,"") -> 77010000110
A274: 77010000128 | B274: 2 | C274: Внутри сети | D274: 4.26 | E274: 10 | H274: =TRIM(Таблиця1[[#This Row],[Абонент]]) -> 77010000128 | J274: =IF(C274="Внутри сети",A274,"") -> 77010000128
...

Sheet Відомості1
A1: Відомості про Кількість з Абонент
A3: Абонент | B3: Тарифный план | C3: Направление звонка | D3: Начисления, тенге | E3: Продолжительность разговора, секунды
A4: 77010000068 | B4: 1 | C4: Внутри сети | D4: 0 | E4: 0
A5: 77010000001 | B5: 1 | C5: Внутри сети | D5: 0.43 | E5: 1
A6: 77010000003 | B6: 1 | C6: Внутри сети | D6: 0.43 | E6: 1
A7: 77010000004 | B7: 1 | C7: Внутри сети | D7: 0.43 | E7: 1
A8: 77010000008 | B8: 1 | C8: Внутри сети | D8: 0.43 | E8: 1
A9: 77010000052 | B9: 1 | C9: Внутри сети | D9: 0.43 | E9: 1
A10: 77010000060 | B10: 1 | C10: Внутри сети | D10: 0.43 | E10: 1
A11: 77010000046 | B11: 1 | C11: Внутри сети | D11: 0.43 | E11: 1
A12: 77010000054 | B12: 1 | C12: Внутри сети | D12: 0.43 | E12: 1
A13: 77010000062 | B13: 1 | C13: Внутри сети | D13: 0.43 | E13: 1
A14: 77010000065 | B14: 1 | C14: Внутри сети | D14: 0.43 | E14: 1
A15: 77010000066 | B15: 1 | C15: Внутри сети | D15: 0.43 | E15: 1
... A626: 77010000246 | B626: 6 | C626: На других операторов | D626: 22.3 | E626: 24

Sheet Sheet2
A1: =VLOOKUP(77010000055,'База данных'!A:B,2,FALSE) -> 1
A2: =SUMIF('База данных'!B:B,"1",'База данных'!E:E) -> 2705
A3: {=INDEX('База данных'!A:A,MATCH(MAX(_xlfn._xlws.FILTER(SUMIF('База данных'!A:A,'База данных'!A:A,'База данных'!E:E),'База данных'!B:B="5")),SUMIF('База данных'!A:A,'База данных'!A:A,'База данных'!E:E),0))} -> #NAME?
M13: =SUMPRODUCT(('База данных'!A2:A1000<>"")/COUNTIF('База данных'!A2:A1000,'База данных'!A2:A1000&"")) -> 292
